<?xml version="1.0"?>
<robot name="ppi2_robot">

	<!-- * * * Link Definitions * * * -->

 	<link name="base_link">
		<visual>
		    <origin xyz="0 0 0.125" rpy="0 0 0"/>
			<geometry>
				<cylinder radius="0.25" length="0.25"/>
			</geometry>
			<material name="color1">
	       		<color rgba="0 5 0.9 1.0"/>
	     	</material>
		</visual>	
	</link>
	
	<link name="link_1">
		<visual>
		    <origin xyz="0 0 0.10" rpy="0 0 0"/>
			<geometry>
				<cylinder radius="0.10" length="0.95"/>
			</geometry>
			<material name="color2">
	       		<color rgba="0 0.7 0.7 1.0"/>
	     	</material>
		</visual>	
	</link>

	<link name="link_2">
		<visual>
		    <origin xyz="0 0 0" rpy="1.57 0 0"/>
			<geometry>
				<cylinder radius="0.10" length="0.50"/>
			</geometry>
			<material name="color3">
	       		<color rgba="0 1 0 1.5"/>
	     	</material>
		</visual>	
	</link>

	<link name="link_3">
		<visual>
		    <origin xyz="0 0 0" rpy="0 0 0"/>
			<geometry>
				<cylinder radius="0.10" length="0.4"/>
			</geometry>
			<material name="color4">
	       		<color rgba="0 0.1 0.1 0.1"/>
	     	</material>
		</visual>	
	</link>

	<link name="link_4">
		<visual>
		    <origin xyz="0 0 0" rpy="1.57 0 0"/>
			<geometry>
				<cylinder radius="0.10" length="0.5"/>
			</geometry>
			<material name="color5">
	       		<color rgba="0 0.1 0.4 0.7"/>
	     	</material>
		</visual>	
	</link>

	<link name="link_5">
		<visual>
		    <origin xyz="0 0 0" rpy="0 0 0"/>
			<geometry>
				<cylinder radius="0.10" length="0.20"/>
			</geometry>
			<material name="color6">
	       		<color rgba="1 0 0 0.1"/>
	     	</material>
		</visual>	
	</link>

	<link name="link_6">
		<visual>
		    <origin xyz="0 0 0" rpy="1.57 0 0"/>
			<geometry>
				<cylinder radius="0.10" length="0.15"/>
			</geometry>
			<material name="color7">
	       		<color rgba="1 1 0 1"/>
	     	</material>
		</visual>	
	</link>

    <link name="efect_base">
      <visual>
        <origin rpy="0 0 0" xyz="0 0 0"/>
        <geometry>
          <box size="0.1 0.25 0.05"/>
        </geometry>
        <material name="color6"/>
      </visual>
    </link>

    <link name="efect_right">
      <visual>
        <origin rpy="0 0 0" xyz="0 0.1 0"/>
        <geometry>
          <box size="0.1 0.05 0.25"/>
        </geometry>
        <material name="color6"/>
      </visual>
    </link>

    <link name="efect_left">
      <visual>
        <origin rpy="0 0 0" xyz="0 -0.1 0"/>
        <geometry>
          <box size="0.1 0.05 0.25"/>
        </geometry>
        <material name="color6"/>
      </visual>
    </link>
	<!-- * * * Joint Definitions * * * -->
	
	<joint name="joint_b_1" type="revolute">
      <axis xyz="0 0 1"/>
      <parent link="base_link"/>
      <child link="link_1"/>
      <origin xyz="0 0 0.60" rpy="0 0 0"/>
	</joint>
 

	<joint name="joint_1_2" type="revolute">
      <axis xyz="0 1 0"/>
      <parent link="link_1"/>
      <child link="link_2"/>
      <origin xyz="0 0.15 0.675" rpy="0 0 0"/>
	</joint> 

	<joint name="joint_2_3" type="revolute">
      <limit lower="-1.57" upper="1.57" effort="30.0" velocity="1"/>
      <axis xyz="0 0 1"/>
      <parent link="link_2"/>
      <child link="link_3"/>
      <origin xyz="0 0.35 0.1" rpy="0 0 0"/>
	</joint> 

	<joint name="joint_3_4" type="revolute">
      <limit lower="-1.57" upper="1.57" effort="30.0" velocity="1"/>
      <axis xyz="0 1 0"/>
      <parent link="link_3"/>
      <child link="link_4"/>
      <origin xyz="0 0.15 0.30" rpy="0 0 0"/>
	</joint> 

	<joint name="joint_4_5" type="revolute">
      <limit lower="-1.57" upper="1.57" effort="30.0" velocity="1"/>
      <axis xyz="0 0 1"/>
      <parent link="link_4"/>
      <child link="link_5"/>
      <origin xyz="0 0.35 0" rpy="0 0 0"/>
	</joint> 

	<joint name="joint_5_6" type="revolute">
      <limit lower="-1.57" upper="1.57" effort="30.0" velocity="1"/>
      <axis xyz="0 1 0"/>
      <parent link="link_5"/>
      <child link="link_6"/>
      <origin xyz="0 0 0.20" rpy="0 0 0"/>
	</joint> 

	<joint name="joint_6_base_efect" type="fixed">
      <axis xyz="0 0 0"/>
      <parent link="link_6"/>
      <child link="efect_base"/>
      <origin xyz="0 0 0.125" rpy="0 0 0"/>
	</joint> 

	<joint name="joint_base_efect_right" type="fixed">
      <axis xyz="0 0 0"/>
      <parent link="efect_base"/>
      <child link="efect_right"/>
      <origin xyz="0 0 0.125" rpy="0 0 0"/>
	</joint> 

	<joint name="joint_6_base_efect_left" type="fixed">
      <axis xyz="0 0 0"/>
      <parent link="efect_base"/>
      <child link="efect_left"/>
      <origin xyz="0 0 0.125" rpy="0 0 0"/>
	</joint> 
</robot>